Workbook

Sheet How We Run
A1: Tage VC — How We Run
A2: Operating home · Deal Flow · Portfolio/Subs · Firm + SS · Portal: Architecture → Spec → Cursor Brief · Brand: Brand & Styling Guide · AI tickets: SS Model §7
A3: ⚠ DATA FRESHNESS (FIRM STANDARD) | B3: BD10 close → BD10–12 pack + Roll-up (Period B13) → BD15 Portfolio Active CORE $ + Health → Command Center must read FRESH. Same period everywhere. STALE = no firm review until Active $ = Roll-up E.
A4: 1 · PICK THE TRACK
A5: Situation | B5: Track | C5: Start here | D5: End state
A6: Startup / growth equity check | B6: VC Invest | C6: Pipeline Active | D6: Wired → Portfolio (investor)
A7: Build something new with us | B7: VC · Launch path | C7: Pipeline (Path=Launch) | D7: Same + heavy operator support
A8: Buy / merge / roll-up control | B8: M&A Buy | C8: M&A Pipeline Active | D8: Acquired → Integration → Portfolio
A9: Real estate asset (resi or CRE) | B9: RE Buy | C9: RE Pipeline Active | D9: Purchased → RE Portfolio
A10: 2 · WEEKLY RHYTHM
A11: When | B11: Ritual | C11: Owner | D11: Sheet | E11: Outcome
A12: Mon | B12: Triage inbound + next actions | C12: Associate | D12: Pipeline / M&A Pipeline | E12: No blank Next Action dates
A13: Tue / Thu | B13: DD + deal blockers standup | C13: Partner | D13: Needs Completed / Deal or M&A Tasks | E13: Unblock or escalate
A14: Wed | B14: IC / terms / LOI review | C14: Partners | D14: Scorecard + Model (+ M&A twins) | E14: Go / conditions / pass
A15: Fri | B15: Command Center pulse | C15: Partner | D15: Command Center | E15: Funnel health + $ in flight
A16: Biweekly | B16: Portfolio ops review | C16: COO | D16: Portfolio Active | E16: Health, risks, asks
A17: As needed | B17: Closing war room | C17: Counsel + Ops | D17: Deal or M&A Tasks | E17: CPs → wire / acquire
A18: Mon (RE) | B18: RE pipeline scrub by Route + sourcer | C18: RE Sourcer / Partner | D18: RE Pipeline Active | E18: Stale deals cleared
A19: 3 · DEAL FLOW (HAPPY PATH)
A20: VC Invest | B20: Source → Screen → Call → Partner → DD + Score + Model → IC → TS → Docs → Wire → Handoff → Portfolio
A21: M&A Buy | B21: Source → CIM → Mgmt → IOI → LOI → QoE/DD → Score + Model → SPA → Close → Integration → Portfolio
A22: RE Buy | B22: Source → Screen → Underwrite (Resi or CRE) → Offer → PSA → Diligence → Close → RE Portfolio
A23: 4 · ROLES
A24: Role | B24: Owns | C24: Does not auto-decide
A25: Associate | B25: Intake, research, tasks, memos, data room | C25: Pass tone; IC vote
A26: Partner | B26: Thesis fit, IC, terms/LOI, board | C26: — (final call on capital)
A27: Counsel / Ops | B27: Docs, CPs, wire, archive | C27: Commercial terms alone
A28: Subsidiary COO | B28: Post-close growth, KPIs, integration | C28: New buys without IC
A29: RE Sourcer (Resi / CRE) | B29: Find assets, underwrite, offer, diligence | C29: Capital commit without Partner
A30: 5 · GOLDEN RULES
A31: 1. One canonical Company name on every sheet (join key).
A32: 2. Every active row has Owner + Next Action + date — no zombies.
A33: 3. Libraries spawn work; humans score, negotiate, and wire.
A34: 4. Complete → archive (never delete history).
A35: 5. Blue = inputs. Black = formulas. Command Center = firm pulse.
A36: 6. VC check ≠ buy the company — pick the track on day one.
A37: 7. Business deals ≠ RE deals — separate pipelines and sourcers.
A38: 6 · WHERE TO CLICK
A39: Need… | B39: Go to…
A40: Firm pulse | B40: Command Center
...

Sheet Brand & Styling Guide
A1: Tage VC — Brand & Styling Guide
A2: Visual standards for all Tage VC and subsidiary workbooks. Apply tab colors and header styles from this guide.
A42: START HERE ORDER
A43: 1) How We Run 2) Brand & Styling Guide 3) Command Center 4) Core Subsidiary Structure 5) Deal / M&A / RE pipelines 6) Portfolio Roll-up 7) Firm + Shared Services
A44: Recruit 619 ops playbook must match this palette and Recruit 619 Alignment KPI names.

Sheet Process Map
A1: Tage VC — Process Map | End-to-End Operating System
A2: Orientation map. Start: How We Run. Build: Portal Architecture. Standards: Core Subsidiary Structure · Brand & Styling Guide.
A4: Phase | B4: Tab color | C4: Order | D4: What happens | E4: Sheets in this phase | F4: Exit to next phase when…
A5: 0 · Map | B5: Warm stone | C5: First | D5: Orientation — how the workbook fits together | E5: Process Map | F5: —
A6: 1 · Source & Evaluate | B6: Slate (brand primary) | C6: 1st | D6: Find leads, screen thesis, first calls, partner meeting | E6: Pipeline Active, Closed, Lead Tasks, Lead Library, Pipeline Notes | F6: Outcome = Advanced to DD (partner approved full DD)
A7: 2 · Due Diligence | B7: Taupe accent | C7: 2nd | D7: Full DD checklist across team, market, product, financials, legal… | E7: Needs Completed, Completed, Checklist Library, Notes | F7: Critical DD done (or waived) + ready for IC
A8: 3 · Execute & Close | B8: Cool slate | C8: 3rd | D8: IC → term sheet → confirmatory DD → docs → wire → post-close | E8: Deal Active, Closed, Deal Tasks, Deal Library, Deal Notes | F8: Outcome = Wired / Closed (portfolio handoff)
A10: End-to-end flow
A11: Step | B11: Action | C11: Primary sheet | D11: ID pattern
A12: 1 | B12: Log lead + source | C12: Pipeline Active | D12: LD-###
A13: 2 | B13: Screen → call → partner → Ready for DD | C13: Lead Tasks + Pipeline | D13: LT-###
A14: 3 | B14: Close pipeline as Advanced to DD | C14: Pipeline Closed | D14: —
A15: 4 | B15: Spawn DD checklist for same Company | C15: Needs Completed | D15: DD-###
A16: 5 | B16: Complete DD; archive tasks | C16: Completed | D16: —
A17: 6 | B17: IC approval | C17: Deal Active (new) | D17: DE-###
A18: 7 | B18: Term sheet negotiate + sign | C18: Deal Tasks Active | D18: DT-###
A19: 8 | B19: Docs + closing conditions + wire | C19: Deal Active / Tasks | D19: —
A20: 9 | B20: Close deal; post-close portfolio | C20: Deal Closed | D20: —
A22: How to read tab colors
A23: Slate = source. Taupe = DD. Cool slate = close. Brand neutrals from site OG/screenshot palette.
A25: Golden rule
A26: One Company name everywhere: Pipeline = DD Entity = Deal Company (join key).
A28: Brand palette (site)
A29: #3A414F | B29: Primary slate — Source tabs + main UI dark
A30: #9F957C | B30: Taupe accent — DD tabs
A31: #535C63 | B31: Cool slate — Execute/Close tabs
A32: #7C7871 | B32: Warm stone — Process Map
A33: #ECE9E6 | B33: Warm sand — page background on site
A34: #D7D3C3 | B34: Light sand — secondary surface
A36: SYSTEM LAYERS (new)
A37: Command Center — firm KPIs (slate tab near Map)
A38: Deal Scorecard + Financial Model — IC analytics (taupe with DD)
A39: Portfolio Handoff + Portfolio Active — COO ops (sage tabs)
A40: Data Dictionary + Platform Spec + Cursor Brief — build the portal (slate)
A41: Flow: Pipeline → Scorecard/Model → DD → Deal desk → Wire → Handoff → Portfolio → (app via Cursor Brief)
A43: TWO TRACKS
A44: A) VC INVEST (slate/taupe/cool) — startup or growth check → Deal desk → Portfolio as investor
A45: B) M&A BUY (steel gray #4A5568) — platform/add-on/merger → LOI → QoE → close → Integration → Portfolio as operator
A46: M&A sheets: M&A Pipeline, Tasks, Library, Scorecard, Model, Integration, Notes
A47: M&A stages: Sourced → CIM → Mgmt → IOI → LOI → DD → Docs → Closing → Integration
...

Sheet Command Center
A1: Tage VC — Command Center | Firm Funnel · Capital · Portfolio Pulse
A2: Read-mostly. Health ← Portfolio Active · Money ← Portfolio Roll-up · Funnel ← pipelines. Fix STALE before firm review. Nav: How We Run.
A3: ⚠ DATA FRESHNESS | B3: Roll-up Period | C3: Active Σ | D3: Roll-up E | E3: Status
A4: Calendar: BD10 close · BD10–12 pack · BD15 Active+Health | B4: =IFERROR('Portfolio Roll-up'!B13,"set B13") -> 2026-03 | C4: ← must match packs | D4: Finance sets period | E4: COO Health on Active only
A5: ARR ($k) | B5: must match → | C5: =IFERROR(SUM(TablePortfolio[ARR ($k)]),0) -> 600 | D5: =IFERROR('Portfolio Roll-up'!E17,0) -> 600 | E5: =IF(ABS(C5-D5)<0.05,"FRESH","STALE") -> FRESH
A6: Net Burn ($k) | B6: must match → | C6: =IFERROR(SUM(TablePortfolio[Net Burn ($k)]),0) -> 75 | D6: =IFERROR('Portfolio Roll-up'!E23,0) -> 75 | E6: =IF(ABS(C6-D6)<0.05,"FRESH","STALE") -> FRESH
A7: Cash ($k) | B7: must match → | C7: =IFERROR(SUM(TablePortfolio[Cash ($k)]),0) -> 1170 | D7: =IFERROR('Portfolio Roll-up'!E24,0) -> 1170 | E7: =IF(ABS(C7-D7)<0.05,"FRESH","STALE") -> FRESH
A8: OVERALL | B8: Health only on Portfolio Active (COO by BD15) | E8: =IF(COUNTIF(E5:E7,"STALE")=0,"✓ FRESH — OK for firm review","✗ STALE — fix before firm review") -> ✓ FRESH — OK for firm review
A9: Blocked DD tasks | B9: =IFERROR(COUNTIF(TableActive[Status],"Blocked"),0) -> 1 | C9: 2 | D9: =IF(B9<=C9,"OK","Escalate") -> OK
A10: FUNNEL SNAPSHOT
A11: Metric | B11: Count | C11: Target | D11: Status
A12: Active leads (pipeline) | B12: =IFERROR(COUNTA(TablePipeline[Lead ID]),0) -> 5 | C12: 25 | D12: =IF(B12>=C12,"On track",IF(B12>=C12*0.7,"Watch","Low")) -> Low
A13: Ready for DD | B13: =IFERROR(COUNTIF(TablePipeline[Pipeline Stage],"Ready for DD"),0) -> 1 | C13: 3 | D13: =IF(B13>=C13,"On track",IF(B13>=1,"Watch","Low")) -> Watch
A14: Open DD tasks | B14: =IFERROR(COUNTA(TableActive[ID]),0) -> 6 | C14: 40 | D14: =IF(B14<=C14,"On track","Heavy load") -> On track
A15: Blocked DD tasks | B15: =IFERROR(COUNTIF(TableActive[Status],"Blocked"),0) -> 1 | C15: 2 | D15: =IF(B15<=C15,"OK","Escalate") -> OK
A16: Active deals (TS→Close) | D16: =IF(B16>=1,"Active","Idle") -> Idle
A17: Deals in closing band | B17: =IFERROR(COUNTIF(TableDeal[Execution Stage],"Closing Conditions")+COUNTIF(TableDeal[Execution Stage],"Signing Ready"),0) -> 0 | C17: 1 | D17: =IF(B17>=C17,"On track",IF(B17=0,"None","Watch")) -> None
A18: Closed wins (log) | B18: =IFERROR(COUNTIF(TableDealClosed[Outcome],"Wired / Closed"),0) -> 1 | C18: 5 | D18: =IF(B18>=C18,"On track","Building") -> Building
A19: Pipeline passes (log) | B19: =IFERROR(COUNTIF(TablePipelineClosed[Outcome],"Pass"),0) -> 1 | D19: —
A20: Advanced to DD (log) | B20: =IFERROR(COUNTIF(TablePipelineClosed[Outcome],"Advanced to DD"),0) -> 1 | D20: —
A21: CONVERSION & QUALITY
A22: Metric | B22: Value | C22: Notes
A23: Screen→DD conversion (closed) | B23: =IFERROR(B20/MAX(B19+B20,1),0) -> 0.5 | C23: Advanced / (Advanced + Pass) from closed log
A24: Strong-fit share of active pipeline | C24: Quality of top of funnel
A25: Critical open DD items | B25: =IFERROR(COUNTIF(TableActive[Priority],"Critical"),0) -> 3 | C25: Must clear before IC
A26: Open lead eval tasks | B26: =IFERROR(COUNTA(TableLeadTasks[Task ID]),0) -> 4 | C26: Pre-DD work in flight
A27: Open deal exec tasks | B27: =IFERROR(COUNTA(TableDealTasks[Task ID]),0) -> 3 | C27: TS→close work in flight
A28: Closed wired check size ($k) | B28: =IFERROR(SUMIF(TableDealClosed[Outcome],"Wired / Closed",TableDealClosed[Check Size ($k)]),0) -> 750
A30: OPERATING CADENCE
A31: Ritual | B31: Owner | C31: Cadence | D31: Sheet
A32: Inbound triage + source ROI | B32: Associate | C32: Daily / Weekly | D32: Pipeline Active / Closed
A33: DD standup (blockers) | B33: Partner | C33: 2x week | D33: Needs Completed
A34: IC + term sheet review | B34: Partners | C34: Weekly | D34: Deal Scorecard + Deal Active
A35: Closing war room | B35: Counsel + Ops | C35: As needed | D35: Deal Tasks Active
A36: Portfolio ops review | B36: Subsidiary COO | C36: Biweekly | D36: Portfolio Active
A38: HOW TO USE THIS SYSTEM
A39: 1. Source in Pipeline → score in Deal Scorecard when serious → DD tasks + Financial Model → IC → Deal Active → wire → Portfolio Handoff.
A40: 2. One Company name everywhere. IDs: LD- / LT- / DD- / DE- / DT- / PH- / PF-.
A41: 3. Blue cells = targets and model inputs. Black = formulas. Command Center is read-mostly.
A42: 4. Platform build: see Platform Spec + Cursor Brief + Data Dictionary.
...

Sheet Portal Architecture
A1: Tage VC — Portal Architecture
A2: High-level build reference from the Excel OS. Detail: Platform Spec · Cursor Brief · Data Dictionary · Core Subsidiary Structure · Portfolio Roll-up.
A4: 1 · OVERALL ARCHITECTURE
A5: Layer | B5: Responsibility | C5: Notes
A6: Frontend | B6: Role-based UI: Command Center, deal boards (VC/M&A/RE), entity/portfolio pages, SS tickets, docs | C6: Next.js + Brand & Styling Guide
A7: Backend / API | B7: Auth, RBAC, CRUD, workflows, roll-up jobs, webhooks, audit log | C7: Enforce enums + CORE/FLEX server-side
A8: Database | B8: Postgres: entities, deals, tasks, pnl, kpi, docs, tickets | C8: Seed from Excel tables
A9: Integrations | B9: QBE/Intuit, DocuSign, object storage, email/calendar, tickets | C9: Human gates on wire + capital DocuSign send
A10: Jobs / agents | B10: Monthly roll-up, SLA clocks, stale leads, draft memos | C10: Agents draft only — no silent capital actions
A12: End-to-end data flow
A13: Inbound → Deal track (VC / M&A / RE) → tasks from libraries → IC/close → issue ENT-* → Handoff → Portfolio Active → QBE monthly pack → entity_month_pnl/kpi → Portfolio Roll-up (SUM/WEIGHTED/MIN/FLAG/COUNT) → Command Center / Firm review. Docs attach at process steps; SS tickets run in parallel.
A15: 2 · CORE MODULES & NAVIGATION
A16: Nav area | B16: What users open | C16: Excel counterpart
A17: Home | B17: Command Center — funnel, portfolio health COUNT, capital pulse | C17: Command Center · Portfolio Roll-up §C–D
A18: Deal Flow · VC | B18: Pipeline, Lead Tasks, DD, Scorecard, Fin Model, Deal Desk | C18: Pipeline* · Lead Tasks* · Needs Completed* · Scorecard · Financial Model · Deal*
A19: Deal Flow · M&A | B19: Targets, tasks, scorecard, model, integration | C19: M&A* tabs
A20: Deal Flow · RE | B20: Resi/CRE pipeline, underwrite, PSA path, RE portfolio | C20: RE* tabs
A21: Portfolio | B21: Portfolio Active, Handoff, Roll-up, entity detail, Core Standard | C21: Portfolio* · Entity Master · Core Subsidiary Structure
A22: Shared Services | B22: Tickets by service, SLAs, close calendar, audits | C22: SS Operating Model · Annual Audit Master
A23: Firm | B23: Capital allocation, firm rhythm, governance | C23: Firm Operations · How We Run
A24: Documents | B24: Library by entity_id, templates, DocuSign status | C24: Document Management & Workflow
A25: Admin | B25: Users, roles, enums, task templates | C25: Data Dictionary · Brand Guide · libraries
A26: Post-close entity page tabs: Overview | Financials | CORE KPIs | FLEX KPIs | Tasks | Docs | SS tickets | Audit.
A28: 3 · ROLE-BASED ACCESS CONTROL (HIGH LEVEL)
A29: Role | B29: Can see / do | C29: Cannot (examples)
A30: Visionary | B30: Full read; capital allocation; CORE exceptions; Critical war rooms | C30: — final capital authority
A31: Partner | B31: Deal tracks; IC; thesis portfolio cos; recovery plans | C31: Change CORE standard alone
A32: Associate / VC Sourcer | B32: VC pipeline, DD, tasks, memos | C32: Wire; set Health; other tracks unless granted
A33: RE Sourcer / M&A Associate | B33: Own track boards + Command Center read | C33: Other tracks by default
A34: COO (Subsidiaries) | B34: Portfolio Active, Health, packs, SS priority, Roll-up | C34: IC approve; silent capital DocuSign
A35: Sub Lead | B35: Own entity ops, KPI inputs, Top Risk, weekly review | C35: Other entities; firm capital
A36: Service Lead (Fin/Legal/HR/IT/Mkt) | B36: Own SS queue, SLAs, QBE close (Finance) | C36: Change deal outcomes
A37: Counsel / Ops | B37: Docs, CPs, wire package, archive | C37: IC commercial decision alone
A38: Admin | B38: Users, templates, enums, seed | C38: Bypass dual-control wire
A40: 4 · KEY DATA MODELS
A41: Model | B41: Purpose | C41: Excel source
A42: entities (Entity Master) | B42: Canonical ENT-*; module; QBE key; parent; portfolio_id | C42: Entity Master
A43: leads / ma_targets / re_deals | B43: Pre-close deal objects by track | C43: Pipeline / M&A / RE Active
A44: deals | B44: VC post-IC execution (TS→wire) | C44: Deal Active/Closed
A45: tasks + task_templates | B45: Work items; spawn from process libraries | C45: *Tasks + *Process Library
...

Sheet Platform Spec
A1: Tage VC Portal — Platform Spec (Current)
A2: Product requirements for the internal portal. Excel workbook is the SSOT prototype. See also Portal Architecture + Cursor Brief.
A4: 1. PRODUCT VISION
A5: One portal for Tage VC: three deal tracks (VC Invest, M&A Buy, RE Buy) → close → Core Subsidiary operations (COO) → firm capital, Shared Services, and governance (Visionary). Operator system, not a pitch portal.
A7: 2. THREE-LAYER MODEL
A8: Layer | B8: Owner | C8: What it covers | D8: Excel SSOT tabs
A9: L1 Deal Flow | B9: Partners + Sourcers | C9: VC / M&A / RE sourcing → diligence → close | D9: Pipeline*, Deal*, M&A*, RE*, scorecards, models, libraries
A10: L2 Portfolio / Subsidiaries | B10: COO of Subsidiaries | C10: Handoff, CORE KPIs, Health, roll-up, sub playbooks | D10: Core Subsidiary Structure, Sub OS, Handoff, Portfolio Active, Portfolio Roll-up, Entity Master, Recruit 619 Alignment
A11: L3 Firm + Shared Services | B11: Visionary + COO (SS stack-rank) | C11: Command Center, capital, SS tickets/SLAs, audits, firm rhythm | D11: Command Center, Firm Operations, SS Model, Annual Audit Master, How We Run
A13: 3. PERSONAS (RBAC)
A14: Visionary · Partner · Associate/VC Sourcer · RE Sourcer · M&A Associate · COO · Sub Lead · Service Lead (Fin/Legal/HR/IT/Mkt) · Counsel/Ops · Admin. Detail can/cannot: Portal Architecture §3 + Cursor Brief.
A16: 4. MODULES (NAV + BUILD ORDER)
A17: ID | B17: Module / Nav | C17: Capabilities | D17: Excel sources
A18: M0 | B18: Identity & Admin | C18: entities, users, RBAC, enums, brand | D18: Entity Master, Data Dictionary, Brand Guide
A19: M1 | B19: Command Center (Home) | C19: Funnel counts, portfolio health COUNT, capital pulse | D19: Command Center, Portfolio Roll-up §C–D
A20: M2 | B20: Deal Flow · VC | C20: Pipeline, lead tasks, DD, scorecard, fin model, deal desk | D20: Pipeline*, Lead Tasks*, Needs Completed*, Scorecard, Financial Model, Deal*
A21: M3 | B21: Deal Flow · M&A | C21: Targets, LOI, QoE tasks, scorecard, model, integration | D21: M&A* tabs
A22: M4 | B22: Deal Flow · RE | C22: Resi/CRE pipeline, underwrite, PSA, RE portfolio | D22: RE* tabs
A23: M5 | B23: Portfolio | C23: Handoff, Portfolio Active, entity page, CORE KPIs, Health, Roll-up job | D23: Core Structure, Handoff, Portfolio Active, Roll-up
A24: M6 | B24: Shared Services | C24: Tickets P0–P3, SLAs, close calendar, audit checklists | D24: SS Operating Model, Annual Audit Master
A25: M7 | B25: Documents | C25: Library by entity_id, templates, DocuSign | D25: Document Management & Workflow
A26: M8 | B26: Firm Operations | C26: Capital allocation, firm rhythm, governance | D26: Firm Operations, How We Run
A27: M9 | B27: Automations / Agents | C27: Stage task spawn, roll-up job, SLA clocks, draft memos | D27: Cursor Brief agent rules
A29: 5. DATA MODEL (CURRENT)
A30: Table | B30: Grain | C30: Key fields / rules
A31: entities | B31: 1 / legal entity | C31: ENT-*, canonical_name, type, parent_id, industry_module, qbe_key, portfolio_id (Entity Master)
A32: leads | ma_targets | re_deals | B32: 1 / pre-close object | C32: LD-/MA-/RE-; join name until ENT issued at close
A33: deals | B33: 1 / VC execution | C33: DE-*; TS→wire stages
A34: tasks + task_templates | B34: 1 / task or library row | C34: LT/DD/DT/MT/RT; spawn from process libraries
A35: dd_items | B35: 1 / DD checklist item | C35: Archive on complete
A36: portfolio_companies | B36: 1 / post-close ops row | C36: PF-*; CORE KPI fields; Health enum
A37: entity_month_pnl | B37: entity × month | C37: Core P&L lines (Revenue…Cash)
A38: entity_month_kpi | B38: entity × month × kpi_key | C38: CORE only; method SUM|WEIGHTED|MIN_FLAG|COUNT|LIST (Core Structure §3)
A39: entity_month_kpi_flex | B39: entity × month × flex_key | C39: Never into portfolio money totals
A40: portfolio_month_rollup | B40: month | C40: SUM money; WEIGHTED % from sums; MIN runway; FLAG <12; health COUNT
A41: firm_month_rollup | B41: month | C41: Firm-only opex/cash + allocation; col F not mixed into sub cols
... A43: tickets | B43: 1 / SS ticket | C43: service, P0–P3, SLA clocks
A44: Join: pre-close canonical_name; post-close entity_id. Enums exact (Data Dictionary). Roll-up authority: Core §3 + Portfolio Roll-up How to Use.
A46: 6. MAJOR WORKFLOWS
A47: VC source→DD→IC→wire · M&A LOI→close→integration · RE underwrite→PSA→purchase · Close→ENT+Handoff+Portfolio · Monthly pack→Roll-up→Health→CC · SS tickets · DocuSign (human send on capital) · Capital allocation review. Detail: Portal Architecture §5.
...

Sheet Cursor Brief
A1: CURSOR BUILD BRIEF — Tage VC Portal (paste into Cursor)
A2: Excel workbook = requirements SSOT. Keep enums exact. Ship modules in order. Brand: Brand & Styling Guide.
A4: ## ROLE
A5: Build the Tage VC internal portal covering Deal Flow (VC + M&A + RE), Portfolio/Core Subsidiary ops, Shared Services, Firm Operations, and Document/DocuSign workflows.
A7: ## READ FIRST (in this order)
A8: 1. Portal Architecture — high-level map, reuse vs rebuild, phases
A9: 2. Platform Spec — L1–L3, modules M0–M9, data model, automation boundaries
A10: 3. Data Dictionary — enums
A11: 4. Entity Master — ENT-* fields
A12: 5. Core Subsidiary Structure §3 — CORE KPI definitions + roll-up methods; §6 Health
A13: 6. Portfolio Roll-up — How to Use + SUM/WEIGHTED/MIN/FLAG/COUNT formulas
A14: 7. Document Management & Workflow — DocuSign human-send rules
... A77: Portal Architecture · Platform Spec · SS Model §7 Grok+Cursor Ticketing · Data Dictionary · Entity Master · Core Structure · Portfolio Roll-up · Document Management · How We Run · Brand & Styling Guide

Sheet Data Dictionary
A1: Tage VC Platform — Data Dictionary (Source of Truth for Build)
A2: Entities, fields, enums, and relationships. Spreadsheet tables map 1:1 to future DB models.
A4: Entity | B4: Sheet / Table | C4: Primary key | D4: Foreign keys | E4: Core fields | F4: Lifecycle
A5: Company | B5: Canonical name across all sheets | C5: company_id (slug) | D5: — | E5: name, website, sector, path, location | F5: Created at first lead
A6: Lead | B6: Pipeline Active / Closed · TablePipeline | C6: LD-### | D6: company_id | E6: source, stage, priority, owner, thesis_fit, score, check_size, next_action | F6: Active→Done
A7: LeadTask | B7: Lead Tasks · TableLeadTasks | C7: LT-### | D7: lead_id, company | E7: process_stage, task, status, owner, due
A8: DdItem | B8: Needs Completed / Completed · TableActive | C8: DD-### | D8: company as Entity | E8: category, item, priority, status, owner, evidence | F8: Open→Completed archive
A9: Deal | B9: Deal Active / Closed · TableDeal | C9: DE-### | D9: lead_id, company | E9: exec_stage, instrument, premoney, check, ownership, ts dates | F9: IC→Wired/Closed
A10: DealTask | B10: Deal Tasks · TableDealTasks | C10: DT-### | D10: deal_id | E10: process_stage, task, status, owner | F10: Active→Done
A11: Scorecard | B11: Deal Scorecard | C11: scorecard_id | D11: company, lead_id | E11: pillar weights/scores, recommendation, IC decision | F11: Versioned per IC
A12: FinancialModel | B12: Financial Model | C12: model_id | D12: company, deal_id | E12: ARR, UE, burn, growth path, MOIC/IRR | F12: Snapshot at IC + close
A13: HandoffPack | B13: Portfolio Handoff | C13: PH-### | D13: deal_id, company | E13: thesis, KPIs, checklist, 30-day plan | F13: At wire
A14: PortfolioCompany | B14: Portfolio Active · TablePortfolio | C14: PF-### | D14: deal_id, company | E14: ARR, burn, runway, health, COO, board lead | F14: Post-close forever
A16: KEY ENUMS (do not invent synonyms in code)
A17: pipeline_stage | B17: Sourced | Screened | First Call | Partner Meeting | Deep Dive Prep | Ready for DD
A18: lead_outcome | B18: Advanced to DD | Pass | Lost | Withdrawn | Nurture archive
A19: dd_status | B19: Not Started | In Progress | Blocked | Waiting on Company | Completed
A20: priority | B20: Critical | High | Medium | Low
A21: exec_stage | B21: IC Approved | Term Sheet | Confirmatory DD | Docs Drafting | Signing Ready | Closing Conditions | Wired / Closed | Post-Close
A22: deal_outcome | B22: Wired / Closed | Dead | Paused
A23: thesis_fit | B23: Strong | Medium | Weak | Unknown
A24: path | B24: Launch | Partner | Exit
A25: portfolio_health | B25: On Track | Watch | At Risk | Critical
A27: JOIN RULE
A28: company.name is the human join key until company_id exists. Never rename mid-flight without updating all child records.
A30: M&A ENTITIES
A31: MATarget | B31: M&A Pipeline · TableMAPipeline | C31: MA-### | D31: company | E31: deal_type, ma_stage, EV, revenue, EBITDA, exclusivity | F31: Active→Acquired/Walked
A32: MATask | B32: M&A Tasks · TableMATasks | C32: MT-### | D32: ma_id | E32: process_stage, task, status | F32: Active→Done
A33: ma_stage | B33: Sourced | CIM Review | Management Meeting | IOI / Indication | LOI / Exclusivity | Confirmatory DD | Definitive Docs | Closing | Integration
A34: ma_outcome | B34: Acquired | Walked | Lost | Paused
A35: ma_deal_type | B35: Platform acquisition | Add-on / roll-up | Merger | Asset purchase | Other
A37: RE ENTITIES
A38: REDeal | B38: RE Pipeline · TableREPipeline | C38: RE-### | D38: — | E38: route, asset_type, stage, ask, offer, NOI, sourcer | F38: Active→Purchased/Passed
A39: RETask | B39: RE Tasks · TableRETasks | C39: RT-### | D39: re_id | E39: route, stage, task, status | F39: Active→Done
A40: REAsset | B40: RE Portfolio · TableREPortfolio | C40: PFRE-### | D40: re_id | E40: basis, NOI, occ, health, PM | F40: Post-close
A41: re_route | B41: Residential | Commercial
A42: re_stage | B42: Sourced | Screen | Underwriting | Offer | LOI / PSA | Diligence | Closing | Onboard
A43: re_outcome | B43: Purchased | Passed | Lost | Paused
A45: DATA MODEL & ROLL-UPS (PORTAL SCHEMA)
A46: Table | B46: Grain | C46: Key fields | D46: Roll-up / notes
...

Sheet Entity Master
A1: Tage VC — Entity Master | Canonical Registry
A2: Single identity for every legal entity (ENT-*). Join key after close. Pre-close deals use canonical_name until ENT issued.
A4: entity_id | B4: canonical_name | C4: legal_name | D4: entity_type | E4: track_origin | F4: parent_entity_id | G4: status | H4: industry_module | I4: qbe_class_or_company | J4: portfolio_id | K4: coo_owner | L4: board_lead | M4: close_date | N4: notes
A5: ENT-FIRM | B5: Tage Venture Capital | C5: Tage Venture Capital LLC | D5: Firm | E5: Firm | F5: — | G5: Active | H5: Firm | I5: QBE: Tage Firm | J5: — | K5: — | L5: Visionary | N5: Parent firm entity
A6: ENT-001 | B6: Sample Closed Co | C6: Sample Closed Co Inc. | D6: Subsidiary | E6: VC Invest | F6: ENT-FIRM | G6: Active | H6: SaaS | I6: QBE: Sample Closed Co | J6: PF-001 | K6: COO — Ops Lead | L6: Partner | M6: 45993 | N6: Launch path
A7: ENT-002 | B7: Instant NDA | C7: Instant NDA LLC | D7: Subsidiary | E7: VC Invest | F7: ENT-FIRM | G7: Active | H7: SaaS | I7: QBE: Instant NDA | J7: PF-002 | K7: COO — Ops Lead | L7: Partner | M7: 45809 | N7: Legal tech
A8: ENT-RE-001 | B8: Sample Indy SFR | C8: Tage RE Holdco SPV 1 | D8: RE Asset Entity | E8: RE Buy | F8: ENT-FIRM | G8: Active | H8: Real Estate Resi | I8: QBE: RE Indy SFR | J8: PFRE-001 | K8: PM — Resi | L8: Partner | M8: 45915 | N8: Residential asset
A9: ENT-R619 | B9: Recruit 619 | C9: Recruit 619 LLC | D9: Subsidiary | E9: VC Invest | F9: ENT-FIRM | G9: Active | H9: Recruiting | I9: QBE: Recruit 619 | J9: PF-R619 | K9: COO — Ops Lead | L9: Partner | N9: Canonical brand Recruit 619 — not 619 Recruiting
A10: ENTITY TYPES
A11: Firm — Tage parent / management company
A12: Subsidiary — operating company (VC Launch/Partner or M&A control)
A13: RE Asset Entity — property SPV or propco
A14: Holdco — intermediate holding company (optional)
A15: Pipeline-only — not yet an owned entity (pre-close); use temporary name until ENT- issued at wire
A17: INDUSTRY MODULES (on top of core subsidiary structure)
A18: Module | B18: Extra KPI pack | C18: Extra playbooks
A19: SaaS / Software | B19: ARR, NRR, CAC, LTV, logo churn | C19: GTM, product ops
A20: Recruiting / Staffing | B20: Placements, GP per desk, fill time | C20: Desk ops, client SLAs
A21: Services / Ops | B21: Utilization, backlog, gross margin by job | C21: Delivery QA
A22: Real Estate Resi | B22: Occ, rent roll, yield on basis, repairs | C22: PM turn process
A23: Real Estate CRE | B23: NOI, occupancy, WALT, capex | C23: Lease abstract ops
A25: RULES
A26: 1. canonical_name never changes without updating all child records (pipelines, portfolio, docs).
A27: 2. At close: issue entity_id, link portfolio_id, create QBE class/company, create Doc library folder.
A28: 3. parent_entity_id defaults to ENT-FIRM unless Holdco structure.
A29: 4. Roll-ups only include status=Active subsidiaries/assets (or period filter).
A31: LINKS: Portfolio Roll-up · Data Dictionary · Portfolio Active · RE Portfolio · Subsidiary Operating System · Document Management & Workflow

Sheet Pipeline Active
A1: Tage VC — VC Pipeline Active | Z1: Sourced
A2: One row per company. Close to Pipeline Closed when Ready for DD or Pass. | Z2: Screened
Z3: First Call
A4: Summary | Z4: Partner Meeting
A5: Active leads | B5: =COUNTA(TablePipeline[Lead ID]) -> 5 | C5: Ready for DD | D5: =COUNTIF(TablePipeline[Pipeline Stage],"Ready for DD") -> 1 | E5: This week next actions | F5: =COUNTIFS(TablePipeline[Next Action Date],">="&TODAY(),TablePipeline[Next Action Date],"<"&TODAY()+7) -> 0 | G5: Strong fit | H5: =COUNTIF(TablePipeline[Thesis Fit],"Strong") -> 2 | Z5: Deep Dive Prep
Z6: Ready for DD
A7: Lead ID | B7: Added Date | C7: Company | D7: Website | E7: Sector | F7: Source | G7: Source Detail | H7: Pipeline Stage | I7: Priority | J7: Owner | K7: Next Action | L7: Next Action Date | M7: Thesis Fit | N7: Raise Stage | O7: Check Size ($k) | P7: Location | Q7: Last Touch | R7: Score (1-5) | S7: Notes | Z7: Critical
A8: LD-001 | B8: 46091 | C8: Acme AI | D8: acme.ai | E8: AI Infra | F8: Warm intro | G8: Jane Doe (portfolio CEO) | H8: Partner Meeting | I8: Critical | J8: Partner | K8: Partner debrief + go/no-go to DD | L8: 46105 | M8: Strong | N8: Seed | O8: 1500 | P8: SF Bay | Q8: 46101 | R8: 5 | S8: Strong team; competitive process — move fast | Z8: High
A9: LD-002 | B9: 46093 | C9: Nova Health | D9: novahealth.io | E9: Healthtech | F9: Inbound | G9: Deck via website | H9: First Call | I9: High | J9: Associate | K9: Founder call + send process email | L9: 46106 | M9: Medium | N9: Series A | O9: 3000 | P9: NYC | Q9: 46099 | R9: 3 | S9: Need clarity on regulatory path | Z9: Medium
A10: LD-003 | B10: 46096 | C10: Beacon Robotics | D10: beaconrobotics.com | E10: Robotics | F10: Event | G10: TechCrunch Disrupt | H10: Screened | I10: Medium | J10: Associate | K10: Desk research + thesis fit memo | L10: 46108 | M10: Unknown | N10: Seed | O10: 1000 | P10: Boston | Q10: 46096 | R10: 3 | S10: Hardware-heavy; confirm fund appetite | Z10: Low
A11: LD-004 | B11: 46099 | C11: Ledgerly | D11: ledgerly.co | E11: Fintech | F11: Cold outreach | G11: Associate outbound | H11: Sourced | I11: Low | J11: Associate | K11: Send intro note; request deck | L11: 46107 | M11: Unknown | N11: Pre-Seed | O11: 500 | P11: Remote | Q11: 46099 | R11: 2 | Z11: Inbound
A12: LD-005 | B12: 46089 | C12: Orbit Data | D12: orbitdata.com | E12: Data/Analytics | F12: Scout | G12: Scout network — Alex R. | H12: Ready for DD | I12: Critical | J12: Partner | K12: Hand off to DD tracker + open data room | L12: 46104 | M12: Strong | N12: Series A | O12: 4000 | P12: Austin | Q12: 46102 | R12: 5 | S12: Partner approved to full DD — spawn DD checklist | Z12: Warm intro
Z13: Cold outreach
Z14: Event
Z15: Scout
Z16: Portfolio
Z17: LP referral
Z18: Other
Z19: Strong
Z20: Medium
Z21: Weak
Z22: Unknown
Z23: Pre-Seed
Z24: Seed
... Z34: Completed

Sheet Pipeline Closed
A1: Tage VC — VC Pipeline Closed (Log) | Z1: Advanced to DD
A2: Leads that Advanced to DD, Passed, or Lost. Keep for source ROI and learning. | Z2: Pass
Z3: Lost
A4: Closed count | B4: =COUNTA(TablePipelineClosed[Lead ID]) -> 2 | C4: Advanced to DD | D4: =COUNTIF(TablePipelineClosed[Outcome],"Advanced to DD") -> 1 | E4: Passed | F4: =COUNTIF(TablePipelineClosed[Outcome],"Pass") -> 1 | Z4: Withdrawn
Z5: Nurture archive
A6: Lead ID | B6: Added Date | C6: Company | D6: Website | E6: Sector | F6: Source | G6: Source Detail | H6: Final Stage | I6: Priority | J6: Owner | K6: Thesis Fit | L6: Raise Stage | M6: Check Size ($k) | N6: Location | O6: Score (1-5) | P6: Outcome | Q6: Outcome Reason | R6: Date Closed | S6: Closed By | T6: Notes
A7: LD-000 | B7: 46042 | C7: Example Pass Co | D7: examplepass.com | E7: Consumer | F7: Inbound | G7: Cold deck | H7: Screened | I7: Low | J7: Associate | K7: Weak | L7: Seed | M7: 750 | N7: LA | O7: 1 | P7: Pass | Q7: Outside thesis — consumer social | R7: 46050 | S7: Associate | T7: Polite pass email sent
A8: LD-010 | B8: 46054 | C8: Example Advanced Co | D8: exampledd.com | E8: B2B SaaS | F8: Warm intro | G8: LP intro | H8: Ready for DD | I8: Critical | J8: Partner | K8: Strong | L8: Series A | M8: 2500 | N8: SF Bay | O8: 5 | P8: Advanced to DD | Q8: Partner approved; DD checklist opened | R8: 46073 | S8: Partner | T8: Link company name to Needs Completed Entity

Sheet Lead Tasks Active
A1: Tage VC — Lead Tasks Active | Z1: Sourced
A2: Pre-DD tasks per company. Move done rows to Lead Tasks Done. | Z2: Screened
Z3: First Call
A4: Open tasks | B4: =COUNTA(TableLeadTasks[Task ID]) -> 4 | C4: Critical / High | D4: =COUNTIFS(TableLeadTasks[Priority],"Critical")+COUNTIFS(TableLeadTasks[Priority],"High") -> 4 | E4: Blocked | F4: =COUNTIF(TableLeadTasks[Status],"Blocked") -> 0 | Z4: Partner Meeting
Z5: Deep Dive Prep
A6: Task ID | B6: Added Date | C6: Company | D6: Lead ID | E6: Process Stage | F6: Task | G6: Priority | H6: Status | I6: Owner | J6: Due Date | K6: Notes | L6: Evidence / Link | Z6: Ready for DD
A7: LT-001 | B7: 46101 | C7: Acme AI | D7: LD-001 | E7: Partner Meeting | F7: Write 1-pager + recommendation for partner | G7: Critical | H7: In Progress | I7: Associate | J7: 46104 | K7: Include comps and kill criteria | Z7: Sourcing Ops
A8: LT-002 | B8: 46099 | C8: Nova Health | D8: LD-002 | E8: First Call | F8: Prep call agenda; review deck + metrics | G8: High | H8: Not Started | I8: Associate | J8: 46106 | Z8: Critical
A9: LT-003 | B9: 46096 | C9: Beacon Robotics | D9: LD-003 | E9: Screened | F9: Thesis fit screen (stage, sector, geo, check size) | G9: Critical | H9: In Progress | I9: Associate | J9: 46108 | K9: Hardware may be edge of mandate | Z9: High
A10: LT-004 | B10: 46102 | C10: Orbit Data | D10: LD-005 | E10: Ready for DD | F10: Handoff: open DD checklist + request data room | G10: Critical | H10: Not Started | I10: Partner | J10: 46104 | K10: Match Entity name on Needs Completed | Z10: Medium
Z11: Low
Z12: Not Started
Z13: In Progress
Z14: Blocked
Z15: Completed

Sheet Lead Tasks Done
A1: Tage VC — Lead Tasks Done (Log)
A2: Completed evaluation tasks. Paste from Lead Tasks Active; set Date Completed.
A4: Done count | B4: =COUNTA(TableLeadTasksDone[Task ID]) -> 1
A6: Task ID | B6: Added Date | C6: Company | D6: Lead ID | E6: Process Stage | F6: Task | G6: Priority | H6: Status | I6: Owner | J6: Due Date | K6: Notes | L6: Evidence / Link | M6: Date Completed | N6: Completed By
A7: LT-000 | B7: 46058 | C7: Example Advanced Co | D7: LD-010 | E7: Screened | F7: Thesis fit screen (stage, sector, geo, check size) | G7: Critical | H7: Completed | I7: Associate | J7: 46059 | K7: Passed thesis screen | M7: 46059 | N7: Associate

Sheet Lead Process Library
A1: Tage VC — Lead Process Library
A2: Copy into Lead Tasks Active when a company enters a stage.
A4: Lib ID | B4: Process Stage | C4: Task | D4: Default Priority | E4: Owner Role | F4: What Good Looks Like
A5: LS-01 | B5: Sourced | C5: Log lead with source, sector, raise stage, owner | D5: Critical | E5: Associate | F5: Complete Pipeline Active row; unique Lead ID
A6: LS-02 | B6: Sourced | C6: Capture deck / one-pager / website in Evidence | D6: High | E6: Associate | F6: Materials linked same day as intake
A7: LS-03 | B7: Sourced | C7: Acknowledge inbound or thank referrer within 48h | D7: High | E7: Associate | F7: Referrer loop closed; founder knows next step
A8: LS-04 | B8: Sourced | C8: Outbound: personalized first touch + follow-up plan | D8: Medium | E8: Associate | F8: 2–3 touch sequence scheduled
A9: LS-05 | B9: Screened | C9: Thesis fit screen (stage, sector, geo, check size) | D9: Critical | E9: Associate | F9: Pass/fail vs fund mandate before deep time
A10: LS-06 | B10: Screened | C10: Quick market map: category, comps, timing | D10: High | E10: Associate | F10: 1-page view of space and positioning
A11: LS-07 | B11: Screened | C11: Team skim: founders LinkedIn, prior companies, signals | D11: High | E11: Associate | F11: Notable strengths/red flags noted
A12: LS-08 | B12: Screened | C12: Traction skim: revenue/users/growth if available | D12: High | E12: Associate | F12: Metrics logged; holes listed for call
A13: LS-09 | B13: Screened | C13: Decide: First Call / Pass / Nurture — update Stage | D13: Critical | E13: Associate | F13: Explicit decision + reason in Notes
A14: LS-10 | B14: Screened | C14: If Pass: send polite decline; close Pipeline row | D14: High | E14: Associate | F14: Outcome + reason on Pipeline Closed
A15: LS-11 | B15: First Call | C15: Prep call agenda; review deck + open questions | D15: High | E15: Associate | F15: Agenda covers problem, product, GTM, ask
... A34: LS-30 | B34: Sourcing Ops | C34: Stale lead sweep (no touch >14 or 30 days) | D34: High | E34: Associate | F34: Advance, nurture, or close — no zombie rows

Sheet Pipeline Notes
A1: Tage VC — Pipeline Notes
A3: Purpose
A4: Cover everything before formal due diligence: source leads, screen against thesis, run first conversations, partner review, then hand off to the DD tracker (Needs Completed).
A6: Sheet map
A7: Pipeline Active — one row per live company (funnel CRM).
A8: Pipeline Closed — Advanced to DD / Pass / Lost / Withdrawn (source ROI + learning).
A9: Lead Tasks Active — evaluation process tasks tied to Company + Lead ID.
A10: Lead Tasks Done — completed eval task archive.
A11: Lead Process Library — 30 standard sourcing/eval steps by stage.
A12: Pipeline Notes — this guide. Links to DD sheets: Needs Completed / Completed / Checklist Library.
A14: Funnel stages (Pipeline Stage)
A15: 1. Sourced — logged, materials requested, first touch.
... A44: Keep enum values exact (dropdowns) so scripts do not fork on synonyms.
A46: Last built | B46: 2026-03-22 — lead pipeline + pre-DD process

Sheet Needs Completed
A1: Tage VC — DD Needs Completed (Active) | Z1: Critical | AA1: Pre-Seed
A2: Open queue — move finished rows to Completed. Blue = inputs. | Z2: High | AA2: Seed
Z3: Medium | AA3: Series A
A4: Summary | Z4: Low | AA4: Series B
A5: Open items | B5: =COUNTA(TableActive[ID]) -> 6 | C5: Critical / High | D5: =COUNTIFS(TableActive[Priority],"Critical")+COUNTIFS(TableActive[Priority],"High") -> 6 | E5: Blocked | F5: =COUNTIF(TableActive[Status],"Blocked") -> 1 | G5: Entities | H5: {=IFERROR(SUMPRODUCT((TableActive[Entity]<>"")/COUNTIFS(TableActive[Entity],TableActive[Entity]&"")),0)} -> 2 | Z5: Not Started | AA5: Series C+
Z6: In Progress | AA6: Growth
A7: ID | B7: Added Date | C7: Entity | D7: Category | E7: Checklist Item | F7: Priority | G7: Status | H7: Owner | I7: Due Date | J7: Deal Stage | K7: Notes | L7: Evidence / Link | Z7: Blocked | AA7: Bridge
A8: DD-001 | B8: 46101 | C8: Acme AI | D8: Team | E8: Founder backgrounds, prior exits/failures, domain expertise | F8: Critical | G8: In Progress | H8: Partner | I8: 46109 | J8: Seed | K8: Reference calls scheduled with 2 prior co-founders | Z8: Waiting on Company | AA8: Other
A9: DD-002 | B9: 46101 | C9: Acme AI | D9: Market | E9: TAM / SAM / SOM and bottom-up market sizing | F9: High | G9: Not Started | H9: Associate | I9: 46116 | J9: Seed | Z9: Completed
A10: DD-003 | B10: 46101 | C10: Acme AI | D10: Product | E10: MVP / product demo; roadmap and tech stack review | F10: High | G10: Not Started | H10: Associate | I10: 46114 | J10: Seed | Z10: Team
A11: DD-004 | B11: 46099 | C11: Nova Health | D11: Legal | E11: Cap table, incorporation docs, shareholder agreements | F11: Critical | G11: Blocked | H11: Counsel | I11: 46106 | J11: Series A | K11: Waiting on data room access from founder | Z11: Market
A12: DD-005 | B12: 46099 | C12: Nova Health | D12: Financials | E12: Historical financials, burn rate, runway, use of funds | F12: Critical | G12: In Progress | H12: Associate | I12: 46111 | J12: Series A | K12: Received P&L through Feb; need cash flow bridge | Z12: Product
A13: DD-006 | B13: 46099 | C13: Nova Health | D13: Traction | E13: CAC, LTV, retention/churn, pipeline and concentration | F13: High | G13: Not Started | H13: Associate | I13: 46117 | J13: Series A | Z13: Traction
Z14: Financials
Z15: Legal
Z16: Tax
Z17: HR
Z18: IT / Security
Z19: Assets
Z20: Risk

Sheet Completed
A1: Tage VC — DD Completed (Log)
A2: Archive log — paste finished rows; set Date Completed.
A4: Completed count | B4: =COUNTA(TableCompleted[ID]) -> 1 | C4: Entities closed (distinct) | D4: {=IFERROR(SUMPRODUCT((TableCompleted[Entity]<>"")/COUNTIFS(TableCompleted[Entity],TableCompleted[Entity]&"")),0)} -> 1
A6: ID | B6: Added Date | C6: Entity | D6: Category | E6: Checklist Item | F6: Priority | G6: Status | H6: Owner | I6: Due Date | J6: Deal Stage | K6: Notes | L6: Evidence / Link | M6: Date Completed | N6: Completed By
A7: DD-000 | B7: 46063 | C7: Example Co | D7: Legal | E7: Confirm Delaware C-Corp formation and good standing | F7: Critical | G7: Completed | H7: Counsel | I7: 46068 | J7: Seed | K7: Certificate of good standing on file | M7: 46067 | N7: Counsel

Sheet Checklist Library
A1: Tage VC — DD Checklist Library
A2: Master list — copy items into Needs Completed per deal.
A4: Lib ID | B4: Category | C4: Checklist Item | D4: Default Priority | E4: Typical Stages | F4: What Good Looks Like / Notes
A5: LIB-01 | B5: Team | C5: Founder backgrounds, prior exits/failures, domain expertise | D5: Critical | E5: All | F5: Relevant operating or technical experience; referenceable track record
A6: LIB-02 | B6: Team | C6: Co-founder dynamics, equity split fairness, vesting & roles | D6: Critical | E6: Pre-Seed–A | F6: 4-year vest / 1-year cliff standard; clear decision rights
A7: LIB-03 | B7: Team | C7: Key hires plan, org chart, ability to recruit/retain | D7: High | E7: Seed+ | F7: Credible 12–18 mo hiring plan matched to use of funds
A8: LIB-04 | B8: Team | C8: Founder references (ex-colleagues, investors, customers) | D8: Critical | E8: All | F8: At least 3 independent references; probe integrity and grit
A9: LIB-05 | B9: Team | C9: Advisor / board composition and value-add | D9: Medium | E9: Seed+ | F9: Relevant domain advisors; no vanity-only boards
A10: LIB-06 | B10: Market | C10: TAM / SAM / SOM and bottom-up market sizing | D10: Critical | E10: All | F10: Bottom-up preferred; $1B+ path for classic VC
A11: LIB-07 | B11: Market | C11: Problem severity, urgency, and willingness to pay | D11: Critical | E11: Pre-Seed–A | F11: Evidence from customers, not only founder narrative
A12: LIB-08 | B12: Market | C12: Competitive landscape, substitutes, SWOT | D12: High | E12: All | F12: Clear differentiation vs direct and indirect competitors
A13: LIB-09 | B13: Market | C13: Market timing / why now (tech, regulation, behavior) | D13: High | E13: All | F13: Structural tailwind, not a fad
A14: LIB-10 | B14: Market | C14: Regulatory / industry structure risks | D14: High | E14: All | F14: Licenses, compliance path, policy exposure mapped
A15: LIB-11 | B15: Product | C15: MVP / product demo; current state vs roadmap | D15: Critical | E15: Pre-Seed–A | F15: Working product; roadmap prioritized by customer value
... A52: LIB-48 | B52: Legal | C52: Data room completeness vs request list; open DD Qs log | D52: High | E52: All | F52: Tracked open items; no silent gaps at IC

Sheet Notes
A1: Tage VC — Notes
A3: Purpose
A4: Track due-diligence work across deals (entities). Keep only open work on Needs Completed. Archive finished work on Completed for logging and audit. Use Checklist Library as the reusable master list when spinning up a new deal.
A6: Sheet map
A7: Needs Completed — live queue of open DD tasks (filter by Entity, Priority, Status, Owner).
A8: Completed — immutable-ish log. Paste finished rows here; set Date Completed + Completed By. Never delete history.
A9: Checklist Library — 48 standard VC DD items across Team, Market, Product, Traction, Financials, Tax, Legal, HR, IT/Security, Assets, Risk.
A10: Notes — this page (method, workflow, Cursor automation hints).
A12: Recommended workflow
A13: 1. Thesis screen first (LIB-45): stage, geo, sector, check size. Kill misfits before deep hours.
A14: 2. New deal: filter Library by stage → copy items into Needs Completed → set Entity, Added Date, Owner, Due Date, unique ID (DD-###).
A15: 3. Weight by stage: Pre-Seed/Seed = Team + Market + Product + basic Legal/Financial hygiene. Series A+ = add Traction unit economics, deeper Financials, Legal, HR, Security.
... A53: Common pillars also include traction, moat, and explicit risk assessment frameworks used by institutional VCs.
A55: Last built | B55: 2026-03-22 — initial VC checklist workbook

Sheet Deal Scorecard
A1: Tage VC — Deal Scorecard
A2: One scorecard per serious deal. Score 1–5. Weighted total drives IC go/no-go. Blue = inputs.
A4: DEAL IDENTITY
A5: Company | B5: Orbit Data | C5: Lead ID | D5: LD-005
A6: Path (Launch/Partner/Exit) | B6: Partner | C6: Raise stage | D6: Series A
A7: Sector | B7: Data/Analytics | C7: Scorer | D7: Partner
A8: Score date | B8: 46103 | C8: IC date | D8: 46109
A10: WEIGHTED SCORE (1=weak … 5=exceptional)
A11: Pillar | B11: Weight | C11: Score 1-5 | D11: Weighted | E11: Evidence / why
A12: Team / founders | B12: 0.2 | C12: 5 | D12: =B12*C12 -> 1 | E12: Prior exit + domain depth
A13: Market size & timing | B13: 0.15 | C13: 4 | D13: =B13*C13 -> 0.6 | E13: Bottom-up SAM credible
A14: Product / moat | B14: 0.15 | C14: 4 | D14: =B14*C14 -> 0.6 | E14: Data network effects early
A15: Traction / unit economics | B15: 0.2 | C15: 4 | D15: =B15*C15 -> 0.8 | E15: NRR >110%, CAC payback <12m
A16: Deal terms / ownership | B16: 0.1 | C16: 3 | D16: =B16*C16 -> 0.3 | E16: Competitive; still 10%+ path
A17: Tage thesis / path fit | B17: 0.1 | C17: 5 | D17: =B17*C17 -> 0.5 | E17: Operator leverage clear
A18: Risk / complexity | B18: 0.1 | C18: 3 | D18: =B18*C18 -> 0.3 | E18: Moderate concentration risk
A19: TOTAL | B19: =SUM(B12:B18) -> 1 | D19: =SUM(D12:D18) -> 4.1 | E19: =IF(ABS(B19-1)>0.001,"FIX WEIGHTS TO 100%","Weights OK") -> Weights OK
A21: DECISION
A22: Score / 5 | B22: =D19 -> 4.1
A23: Recommendation | B23: =IF(B22>=4,"Strong advance",IF(B22>=3.25,"Advance with conditions",IF(B22>=2.5,"Watch / more work","Pass"))) -> Strong advance
A24: IC decision | B24: Advance
A25: Conditions / kill criteria | B25: Confirm top-3 customer refs; ownership ≥10% post-money
A27: UPSIDE FRAME
A28: Base case | B28: Category leader; strategic exit 5–7y
A29: Bull case | B29: Multi-vertical platform; $100m+ ARR path
A30: Bear case | B30: Niche stall; secondary only
A31: Tage value-add | B31: GTM, recruiting, partnerships, board ops
A33: 5=top decile · 4=strong · 3=ok · 2=weak · 1=red flag. Risk: 5=clean, 1=severe. Launch weights Team/Market; Partner Traction/Terms; Exit Risk/Terms.

Sheet Financial Model
A1: Tage VC — Financial Model
A2: Per-deal model. Blue = company/assumptions inputs. Links to scorecard judgment; does not replace full quality of earnings.
A4: COMPANY & ROUND
A5: Company | B5: Orbit Data
A6: Instrument | B6: Priced Equity
A7: Pre-money ($m) | B7: 45
A8: Raise size ($m) | B8: 12
A9: Tage check ($m) | B9: 4
A10: Post-money ($m) | B10: =B7+B8 -> 57
A11: Tage ownership % | B11: =IFERROR(B9/B10,0) -> 0.070175439
A12: Option pool post % | B12: 0.1
A14: TRACTION & UNIT ECONOMICS (TTM / current)
A15: ARR ($k) | B15: 3200
A16: ARR growth YoY | B16: 0.85
A17: Gross margin | B17: 0.78
A18: Net revenue retention | B18: 1.15
A19: Logo churn (annual) | B19: 0.08
A20: CAC ($) | B20: 18000
A21: LTV ($) | B21: 95000
A22: LTV / CAC | B22: =IFERROR(B21/B20,0) -> 5.2777778
A23: CAC payback (months) | B23: 11
A24: Gross burn ($k/mo) | B24: 280
A25: Net burn ($k/mo) | B25: 140
A26: Cash ($k) | B26: 2100
A27: Runway months (pre-round) | B27: =IFERROR(B26/B25,0) -> 15
A28: Runway months (post Tage+round approx) | B28: =IFERROR((B26+B8*1000)/B25,0) -> 100.71429
A30: FORWARD ARR PATH ($k)
A31: Year | B31: 0 (now) | C31: 1 | D31: 2 | E31: 3 | F31: 4 | G31: 5
A32: Growth rate | B32: — | C32: 0.7 | D32: 0.55 | E32: 0.4 | F32: 0.3 | G32: 0.25
A33: ARR ($k) | B33: =B15 -> 3200 | C33: =B33*(1+C32) -> 5440 | D33: =C33*(1+D32) -> 8432 | E33: =D33*(1+E32) -> 11804.8 | F33: =E33*(1+F32) -> 15346.24 | G33: =F33*(1+G32) -> 19182.8
A35: RETURNS (simplified ownership held to exit)
A36: Exit year | B36: 5
A37: Exit ARR multiple | B37: 10
A38: Exit ARR ($k) | B38: =G33 -> 19182.8
A39: Exit enterprise value ($m) | B39: =B38*B37/1000 -> 191.828
A40: Dilution to exit (remaining ownership factor) | B40: 0.7
A41: Tage ownership at exit | B41: =B11*B40 -> 0.049122807
A42: Tage proceeds ($m) | B42: =B39*B41 -> 9.4231298
A43: MOIC | B43: =IFERROR(B42/B9,0) -> 2.3557825
A44: Approx gross IRR (simple) | B44: =IFERROR((B43)^(1/B36)-1,0) -> 0.18693527
...

Sheet Deal Active
A1: Tage VC — Deal Active | Z1: IC Approved | AA1: Critical | AB1: Priced Equity
A2: One row per live deal post-DD. Close when Wired/Closed or Dead. | Z2: Term Sheet | AA2: High | AB2: SAFE
Z3: Confirmatory DD | AA3: Medium | AB3: Convertible Note
A4: Summary | Z4: Docs Drafting | AA4: Low | AB4: Other
A5: Active deals | B5: =COUNTA(TableDeal[Deal ID]) -> 2 | C5: In closing | D5: =COUNTIF(TableDeal[Execution Stage],"Closing Conditions")+COUNTIF(TableDeal[Execution Stage],"Signing Ready") -> 0 | E5: Term sheet out | F5: =COUNTIF(TableDeal[Execution Stage],"Term Sheet") -> 0 | G5: Critical priority | H5: =COUNTIF(TableDeal[Priority],"Critical") -> 2 | Z5: Signing Ready
Z6: Closing Conditions
A7: Deal ID | B7: Added Date | C7: Company | D7: Lead ID | E7: Execution Stage | F7: Priority | G7: Owner | H7: Counsel | I7: Instrument | J7: Pre-Money ($m) | K7: Check Size ($k) | L7: Target Own % | M7: TS Sent Date | N7: TS Signed Date | O7: Exclusivity End | P7: Target Close | Q7: Next Action | R7: Next Action Date | S7: Notes | Z7: Wired / Closed
A8: DE-001 | B8: 46103 | C8: Orbit Data | D8: LD-005 | E8: IC Approved | F8: Critical | G8: Partner | H8: Firm Counsel | I8: Priced Equity | J8: 45 | K8: 4000 | L8: 0.12 | P8: 46142 | Q8: Draft term sheet; partner approve economics | R8: 46106 | S8: DD complete; IC passed 3/21 | Z8: Post-Close
A9: DE-002 | B9: 46091 | C9: Example Advanced Co | D9: LD-010 | E9: Docs Drafting | F9: Critical | G9: Partner | H9: Firm Counsel | I9: Priced Equity | J9: 28 | K9: 2500 | L9: 0.1 | M9: 46086 | N9: 46093 | O9: 46124 | P9: 46127 | Q9: SPA markup round 2 with co counsel | R9: 46107 | S9: TS signed; board seat agreed

Sheet Deal Closed
A1: Tage VC — Deal Closed (Log) | Z1: Wired / Closed
A2: Wired/Closed or Dead deals. Keep for portfolio handoff and learning. | Z2: Dead
Z3: Paused
A4: Closed count | B4: =COUNTA(TableDealClosed[Deal ID]) -> 1 | C4: Wired/Closed | D4: =COUNTIF(TableDealClosed[Outcome],"Wired / Closed") -> 1 | E4: Dead | F4: =COUNTIF(TableDealClosed[Outcome],"Dead") -> 0
A6: Deal ID | B6: Added Date | C6: Company | D6: Lead ID | E6: Final Stage | F6: Instrument | G6: Pre-Money ($m) | H6: Check Size ($k) | I6: Final Own % | J6: TS Signed Date | K6: Close Date | L6: Outcome | M6: Outcome Reason | N6: Owner | O6: Notes
A7: DE-000 | B7: 45962 | C7: Sample Closed Co | D7: LD-099 | E7: Wired / Closed | F7: SAFE | H7: 750 | I7: 0 | J7: 45976 | K7: 45993 | L7: Wired / Closed | M7: Closed on SAFE; post-close portfolio kickoff done | N7: Partner | O7: Handed to portfolio ops

Sheet Deal Tasks Active
A1: Tage VC — Deal Tasks Active | Z1: IC Approved | AA1: Critical | AB1: Not Started
A2: IC → term sheet → docs → close tasks. Move done rows to Deal Tasks Done. | Z2: Term Sheet | AA2: High | AB2: In Progress
Z3: Confirmatory DD | AA3: Medium | AB3: Blocked
A4: Open tasks | B4: =COUNTA(TableDealTasks[Task ID]) -> 3 | C4: Critical / High | D4: =COUNTIFS(TableDealTasks[Priority],"Critical")+COUNTIFS(TableDealTasks[Priority],"High") -> 3 | E4: Blocked | F4: =COUNTIF(TableDealTasks[Status],"Blocked") -> 0 | Z4: Docs Drafting | AA4: Low | AB4: Waiting on Company
Z5: Signing Ready | AB5: Completed
A6: Task ID | B6: Added Date | C6: Company | D6: Deal ID | E6: Process Stage | F6: Task | G6: Priority | H6: Status | I6: Owner | J6: Due Date | K6: Notes | L6: Evidence / Link | Z6: Closing Conditions
A7: DT-001 | B7: 46103 | C7: Orbit Data | D7: DE-001 | E7: Term Sheet | F7: Draft term sheet economics and key rights | G7: Critical | H7: In Progress | I7: Partner | J7: 46106 | K7: IC approved economics band | Z7: Wired / Closed
A8: DT-002 | B8: 46095 | C8: Example Advanced Co | D8: DE-002 | E8: Docs Drafting | F8: SPA / investment docs markup and issue list | G8: Critical | H8: In Progress | I8: Counsel | J8: 46107 | K8: Round 2 open points on liability cap | Z8: Post-Close
A9: DT-003 | B9: 46095 | C9: Example Advanced Co | D9: DE-002 | E9: Docs Drafting | F9: Charter / COI amendments and board consents drafted | G9: High | H9: Not Started | I9: Counsel | J9: 46109

Sheet Deal Tasks Done
A1: Tage VC — Deal Tasks Done (Log)
A2: Completed execution tasks. Paste from Deal Tasks Active; set Date Completed.
A4: Done count | B4: =COUNTA(TableDealTasksDone[Task ID]) -> 1
A6: Task ID | B6: Added Date | C6: Company | D6: Deal ID | E6: Process Stage | F6: Task | G6: Priority | H6: Status | I6: Owner | J6: Due Date | K6: Notes | L6: Evidence / Link | M6: Date Completed | N6: Completed By
A7: DT-000 | B7: 46091 | C7: Example Advanced Co | D7: DE-002 | E7: Term Sheet | F7: Negotiate and sign term sheet | G7: Critical | H7: Completed | I7: Partner | J7: 46093 | K7: Signed 3/12 | M7: 46093 | N7: Partner

Sheet Deal Process Library
A1: Tage VC — Deal Process Library
A2: Copy into Deal Tasks Active when a deal enters each stage.
A4: Lib ID | B4: Process Stage | C4: Task | D4: Default Priority | E4: Owner Role | F4: What Good Looks Like
A5: DX-01 | B5: IC Approved | C5: Finalize IC memo with DD findings and recommendation | D5: Critical | E5: Partner | F5: Memo includes risks, kill criteria, return case
A6: DX-02 | B6: IC Approved | C6: Hold IC; record vote and any conditions | D6: Critical | E6: Partner | F6: Written approval + conditions logged
A7: DX-03 | B7: IC Approved | C7: Open Deal Active row (DE-###); link Lead ID + Company | D7: Critical | E7: Associate | F7: Same Company string as DD Entity
A8: DX-04 | B8: IC Approved | C8: Engage counsel; open matter and conflict check | D8: High | E8: Partner | F8: Counsel assigned on Deal Active
A9: DX-05 | B9: Term Sheet | C9: Draft term sheet economics and key rights | D9: Critical | E9: Partner | F9: Valuation, check, ownership, board, pool, pro rata
A10: DX-06 | B10: Term Sheet | C10: Internal review of TS vs IC authority | D10: Critical | E10: Partner | F10: Within IC band or re-approval noted
A11: DX-07 | B11: Term Sheet | C11: Send TS to founder / company counsel | D11: Critical | E11: Partner | F11: TS Sent Date set
A12: DX-08 | B12: Term Sheet | C12: Negotiate TS markups; track open commercial points | D12: Critical | E12: Partner | F12: Issue list current until signed
A13: DX-09 | B13: Term Sheet | C13: Sign term sheet; set exclusivity / no-shop end date | D13: Critical | E13: Partner | F13: TS Signed + Exclusivity End populated
A14: DX-10 | B14: Term Sheet | C14: Announce process timeline and working group | D14: High | E14: Associate | F14: Target Close agreed with company
A15: DX-11 | B15: Confirmatory DD | C15: Confirmatory legal DD request list to company counsel | D15: Critical | E15: Counsel | F15: Aligned with open DD tracker items
... A36: DX-32 | B36: Post-Close | C36: Archive data room + deal folder; lessons learned note | D36: Medium | E36: Associate | F36: Searchable archive for future deals

Sheet Deal Notes
A1: Tage VC — Deal Notes
A3: Purpose
A4: After DD + IC: TS → docs → close → portfolio handoff.
A6: Sheet map
A7: Deal Active — one row per live deal (economics + stage + dates).
A8: Deal Closed — Wired/Closed or Dead outcomes.
A9: Deal Tasks — execution checklist (lead/DD pattern).
A10: Deal Process Library — 32 standard IC→Close steps.
A12: Execution stages
A13: IC → Term Sheet → Confirmatory DD → Docs → Signing → CPs → Wire → Post-Close
A15: Workflow
A16: 1. IC approve → open Deal Active (DE-###); match Company name.
... A24: IDs DE/LD. Join on Company. See Data Dictionary.
A26: Last built | B26: 2026-03-22 — deal execution tracker

Sheet M&A Pipeline Active
A1: Tage VC — M&A Pipeline Active | Z1: Sourced | AA1: Critical | AB1: Platform acquisition | AC1: Strong
A2: One row per target company. Separate from VC check deals. Close when Closed or Walked. | Z2: CIM Review | AA2: High | AB2: Add-on / roll-up | AC2: Medium
Z3: Management Meeting | AA3: Medium | AB3: Merger | AC3: Weak
A4: Active targets | B4: =COUNTA(TableMAPipeline[MA ID]) -> 2 | C4: In exclusivity | D4: =COUNTIF(TableMAPipeline[MA Stage],"LOI / Exclusivity") -> 1 | E4: LOI out | F4: =COUNTIF(TableMAPipeline[MA Stage],"IOI / Indication")+COUNTIF(TableMAPipeline[MA Stage],"LOI / Exclusivity") -> 1 | Z4: IOI / Indication | AA4: Low | AB4: Asset purchase | AC4: Unknown
Z5: LOI / Exclusivity | AB5: Other
A6: MA ID | B6: Added Date | C6: Target Company | D6: Website | E6: Sector | F6: Deal Type | G6: Source | H6: MA Stage | I6: Priority | J6: Owner | K6: Enterprise Value ($m) | L6: Revenue ($m) | M6: EBITDA ($m) | N6: Next Action | O6: Next Action Date | P6: Exclusivity End | Q6: Strategic Fit | R6: Notes | Z6: Confirmatory DD
A7: MA-001 | B7: 46082 | C7: Midwest Ops Co | D7: midwestops.example | E7: Business services | F7: Platform acquisition | G7: Broker | H7: LOI / Exclusivity | I7: Critical | J7: Partner | K7: 18 | L7: 12 | M7: 2.4 | N7: Quality of earnings kickoff | O7: 46107 | P7: 46143 | Q7: Strong | R7: Owner retirement; add-on pipeline exists | Z7: Definitive Docs
A8: MA-002 | B8: 46093 | C8: Regional Add-On LLC | D8: regionaladdon.example | E8: Business services | F8: Add-on / roll-up | G8: Proprietary | H8: Management Meeting | I8: High | J8: Associate | K8: 4.5 | L8: 3.2 | M8: 0.7 | N8: Site visit + customer refs | O8: 46109 | Q8: Medium | R8: Bolt onto Midwest Ops platform thesis | Z8: Closing
Z9: Integration

Sheet M&A Pipeline Closed
A1: Tage VC — M&A Pipeline Closed (Log) | Z1: Acquired
A2: Acquired / Walked / Lost. Keep for thesis learning and broker ROI. | Z2: Walked
Z3: Lost
A4: Closed count | B4: =COUNTA(TableMAClosed[MA ID]) -> 1 | C4: Acquired | D4: =COUNTIF(TableMAClosed[Outcome],"Acquired") -> 0 | E4: Walked | F4: =COUNTIF(TableMAClosed[Outcome],"Walked") -> 1 | Z4: Paused
A6: MA ID | B6: Added Date | C6: Target Company | D6: Deal Type | E6: Final Stage | F6: EV ($m) | G6: Revenue ($m) | H6: EBITDA ($m) | I6: Outcome | J6: Outcome Reason | K6: Close Date | L6: Owner | M6: Notes
A7: MA-000 | B7: 45870 | C7: Example Walk Co | D7: Platform acquisition | E7: Confirmatory DD | F7: 22 | G7: 14 | H7: 1.1 | I7: Walked | J7: Customer concentration + QoE gaps | K7: 45945 | L7: Partner | M7: Lessons in QoE scope

Sheet M&A Tasks Active
A1: Tage VC — M&A Tasks Active | Z1: Sourced | AA1: Critical | AB1: Not Started
A2: Acquisition work items. Move done rows to M&A Tasks Done. | Z2: CIM Review | AA2: High | AB2: In Progress
Z3: Management Meeting | AA3: Medium | AB3: Blocked
A4: Open tasks | B4: =COUNTA(TableMATasks[Task ID]) -> 2 | C4: Critical / High | D4: =COUNTIFS(TableMATasks[Priority],"Critical")+COUNTIFS(TableMATasks[Priority],"High") -> 2 | Z4: IOI / Indication | AA4: Low | AB4: Completed
Z5: LOI / Exclusivity
A6: Task ID | B6: Added Date | C6: Target Company | D6: MA ID | E6: Process Stage | F6: Task | G6: Priority | H6: Status | I6: Owner | J6: Due Date | K6: Notes | Z6: Confirmatory DD
